<?xml version="1.0"?>
<robot xmlns:xacro="http://www.ros.org/wiki/xacro" name="wheeled_robot">

  <xacro:property name="pi_const" value="3.14159265" />

  <xacro:property name="length" value="0.3" />
  <xacro:property name="width" value="0.4" />
  <xacro:property name="height" value="0.15" />
  
  <xacro:property name="diameter" value="0.1" />
  <xacro:property name="radius" value="${diameter / 2}" />
  <xacro:property name="thickness" value="0.01" />
  
  <xacro:property name="center_to_wheel_x" value="${width/2 + thickness/2}" />
  <xacro:property name="center_to_wheel_y" value="${diameter}" />
  <xacro:property name="center_to_ground_z" value="${height/2 + radius}" />
  <xacro:property name="center_to_caster_y" value="${diameter}" />
  
  <xacro:property name="d1" value="2718.0" />
  <xacro:property name="d2" value="2718.0" />
  <xacro:property name="d3" value="2718.0" />

  <xacro:property name="m1" value="${d1 * width * height * length}" />
  <xacro:property name="m2" value="${d2 * pi_const * radius * radius * thickness}" />
  <xacro:property name="m3" value="${d3 * (4.0 / 3.0) * pi_const * radius * radius * radius}" />


  <xacro:property name="Ix_body" value="${(1 / 12) * m1 * (height * height + width * width)}" />
  <xacro:property name="Iy_body" value="${(1 / 12) * m1 * (length * length + height * height)}" />
  <xacro:property name="Iz_body" value="${(1 / 12) * m1 * (length * length + width * width)}" />


  <xacro:property name="Iz_wheel" value="${0.5 * m2 * radius * radius}" />
  <xacro:property name="I_wheel" value="${(1.0 / 12.0) * m2 * (3.0 * radius * radius + thickness * thickness)}" />

  <xacro:property name="I_caster" value="${(2.0 / 5.0) * m3 * radius * radius}" />

  <material name="black" >
    <color rgba="0 0 0 1" />
  </material>

  <material name="white" >
    <color rgba="1 1 1 1" />
  </material>
  
  <material name="cyan" >
    <color rgba="0 0.4 0.5 1" />
  </material>
  
  <material name="blue" >
    <color rgba="0 0 0.5 1" />
  </material>

  <link name="base_link" />
  
  <link name="robot_base_link">

    <visual>

      <geometry>
        <box size="${width} ${length} ${height}" />
      </geometry>
      <material name="cyan" />
      <origin xyz="0 0 ${height/2}" rpy="0 0 0" />

    </visual>

    <collision>
     
      <geometry>
        <box size="${width} ${length} ${height}" />       
      </geometry>
      <origin xyz="0 0 ${height/2}" rpy="0 0 0" />

    </collision>

    <inertial>
      <origin rpy="0 0 0" xyz="0 0 ${center_to_ground_z}" />
      <mass value="${m1}" />
      <inertia ixx="${Ix_body}" ixy="0.0" ixz="0.0" iyy="${Iy_body}" iyz="0.0" izz="${Iz_body}" />
    </inertial>
  </link>
  
  <link name="apriltag_link">

    <visual>
      <geometry>
        <mesh filename="$(find robot_sim)/urdf/wheeled_robot/apriltag.dae" scale="0.3 0.3 1"/>
      </geometry>
      <origin xyz="0 0 0" rpy="0 0 0" />
    </visual>

    <collision>
     
      <geometry>
        <mesh filename="$(find robot_sim)/urdf/wheeled_robot/apriltag.dae" scale="0.3 0.3 1"/>
      </geometry>
      <origin xyz="0 0 0" rpy="0 0 0" />

    </collision>

    <inertial>
      <origin rpy="0 0 0" xyz="0 0 0" />
      <mass value="0.00001" />
      <inertia ixx="0.00001" ixy="0.0" ixz="0.0" iyy="0.00001" iyz="0.0" izz="0.00001" />
    </inertial>
  </link>

  <joint name="base_robot_base_joint" type="fixed" >
    <parent link="base_link" />
    <child link="robot_base_link" />
    <origin xyz="0 0 0.2" rpy="0 0 0" />
  </joint>

  <joint name="apriltag_base_robot_joint" type="fixed" >
    <parent link="robot_base_link" />
    <child link="apriltag_link" />
    <origin xyz="0 0 ${height}" rpy="0 0 ${pi_const / 2}" />
  </joint>

  <link name="left_wheel_link"> 
    <visual>
      
      <material name="black" />
      <geometry>
        <cylinder length="${thickness}" radius="${radius}" />
      </geometry>
      <origin xyz="0 0 0" rpy="0 ${pi_const / 2} 0" />

    </visual>

    <collision>

      <geometry>
        <cylinder length="${thickness}" radius="${radius}" />
      </geometry>
      
      <origin xyz="0 0 0" rpy="0 ${pi_const / 2} 0" />
    
    </collision>
    <inertial>
    
      <origin rpy="${pi_const / 2} 0 0" xyz="0 0 0" />
      <mass value="${m2}" />
      <inertia ixx="${I_wheel}" ixy="0.0" ixz="0.0" iyy="${I_wheel}" iyz="0.0" izz="${Iz_wheel}" />
    
    </inertial>
  </link>

  <joint name="robot_base_left_wheel_joint" type="continuous">

    <axis xyz="1 0 0"/>
    <parent link="robot_base_link" />
    <child link="left_wheel_link" />
    <origin xyz="${center_to_wheel_x} ${-center_to_wheel_y} 0" rpy="0 0 0" />

  </joint>

  <link name="right_wheel_link"> 
    <visual>
      <material name="black" />
      <geometry>
        <cylinder length="${thickness}" radius="${radius}" />
      </geometry>
      <origin xyz="0 0 0" rpy="0 ${pi_const / 2} 0" />
    </visual>
    <collision>

      <geometry>
        <cylinder length="${thickness}" radius="${radius}" />
      </geometry>
      <origin xyz="0 0 0" rpy="0 ${pi_const / 2} 0" />
    
    </collision>
    <inertial>
      <origin rpy="${pi_const / 2} 0 0" xyz="0 0 0" />
      <mass value="${m2}" />
      <inertia ixx="${I_wheel}" ixy="0.0" ixz="0.0" iyy="${I_wheel}" iyz="0.0" izz="${Iz_wheel}" />
    </inertial>
  </link>

  <joint name="robot_base_right_wheel_joint" type="continuous">

    <axis xyz="1 0 0" rpy="0 0 0"/>
    <parent link="robot_base_link" />
    <child link="right_wheel_link" />
    <origin xyz="${-center_to_wheel_x} ${-center_to_wheel_y} 0" rpy="0 0 0" />

  </joint>

  <link name="caster_wheel_link">
    
    <visual>
      <material name="black" />
      <geometry>
        <sphere radius="${radius}"/>
      </geometry>
      <origin xyz="0 0 0" rpy="0 0 0" />
    </visual>

    <collision>

      <geometry>
        <sphere radius="${radius}"/>
      </geometry>
      <origin xyz="0 0 0" rpy="0 0 0" />
    
    </collision>
    <inertial>
      <mass value="${m3}" />
      <inertia ixx="${I_caster}" ixy="0.0" ixz="0.0" iyy="${I_caster}" iyz="0.0" izz="${I_caster}" />
    </inertial>
  </link>

  <joint name="robot_base_caster_wheel_joint" type="fixed">
    
    <parent link="robot_base_link" />
    <child link="caster_wheel_link" />
    <origin xyz="0 ${center_to_caster_y} 0" rpy="0 0 0" />

  </joint>

  <xacro:include filename="$(find robot_sim)/urdf/wheeled_robot/wheeled_robot.gazebo" />



</robot>

